# 使用试配块的 F#异常处理

> 原文：<https://www.javatpoint.com/f-sharp-example-without-try-with>

F#提供*try-带*关键字处理异常。Try block 用于封闭可疑代码。带有块的*作为处理程序处理由 try 块引发的异常。让我们看一个例子。*

```

let ExExample a b =
  let mutable c = 0
  try
    c <- (a/b)
  with
    | :? System.DivideByZeroException as e -> printfn "%s" e.Message
  printfn "Rest of the code"

ExExample 10 0

```

输出:

```
Attempted to divide by zero.
Rest of the code

```

* * *

## F#尝试-最后一个处理异常的例子

Try-Finally 块用于在异常发生后释放资源。资源可以是输入、输出、存储器或网络等。

```

let ExExample a b =
    let mutable c = 0
    try
        try
            c  printfn "%s" e.Message
    finally 
        printfn "Finally block is executed"
    printfn "Rest of the code"

ExExample 10 0

```

输出:

```
Attempted to divide by zero.
Finally block is executed
Rest of the code

```