# PowerShell 尝试最终捕获

> 原文：<https://www.javatpoint.com/powershell-try-catch-finally>

当您需要处理脚本块中的终止错误时，在 PowerShell 中使用 **Try，Catch，最后是**块。

终止错误是那些阻止语句运行的错误。当 PowerShell 不以某种方式处理终止错误时，它也会停止使用当前管道运行脚本或函数。在其他语言中，如 C 语言，这些错误被称为异常。

## 尝试{........}

**Try block** 是脚本中希望 PowerShell 监控错误的部分。当该块中出现错误时，它首先存储在自动变量 **$Error 中。**之后，PowerShell 搜索 **Catch** 块进行处理。

如果 **Try** 块没有匹配的 **Catch** 块，那么 PowerShell 在父范围中搜索适当的 **Trap 或 Catch** 块。

**尝试块的语法**

下面的框显示了 try 块的语法:

```

try 
{
          Statement-1
          Statement-2
          Statement-N
}          

```

Try 语句必须至少有一个 catch 或一个 finally 块。在上面的语法中，Try 关键字后面是大括号中的单个或多个语句。

## Catch {.....}

**Catch 块**是脚本中处理 Try 块产生的错误的部分。我们可以定义 Catch 块要处理哪种类型的错误。一种类型的错误是微软的例外.NET 框架。A **尝试**块可以有多个不同类型错误的捕捉块。除了**捕捉**块，您还可以使用**陷阱**块来处理错误。

**捕捉块的语法**

下面的框显示了 catch 块的语法:

```

catch [ [<error type>] [',' <error type>] *] 
{
          Statement-1
          Statement-2
          Statement-N
}     

```

括号中显示了错误的类型。最外面的括号表明该元素是可选的。在上面的语法中， **catch** 关键字后面是可选的错误类型规范列表和语句列表。当找到任何 catch 块时，就会执行 catch 块中的语句。

## 最后{......}

**“finally”**块是脚本的一部分，用于释放脚本不再需要的资源。

下面的框显示了 Finally 块的语法:

```

finally
{
          Statement-1
          Statement-2
          Statement-N
}          

```

“finally”块后面是一个或多个语句，这些语句包含在每次执行脚本时执行的大括号中。

### 例子

**示例 1:** 以下示例仅使用一个**用**捕捉**块，尝试**块:

```

Try
{
Get-ChildItem
}
catch
{
"Error in a Try block."
}

```

在本例中，Try 块中的命令是正确的，因此没有错误，并显示以下输出:

```
    Directory: C:\
Mode      LastWrite        Time         Length Name
----           -------------       ------            ----
d-----       23-02-2019     13:14                found.000
d-----       28-12-2017     19:44                Intel
d-----       15-09-2018     13:03                PerfLogs
d-----       09-10-2019     11:20                powershell
d-r---       15-11-2019     12:01                Program Files
d-r---       15-11-2019     12:23                Program Files (x86)
d-----       22-08-2019     15:20                Temp
d-----       13-07-2019     09:55                TURBOC3
d-r---       29-09-2019     16:20                Users
d-----       15-11-2019     18:06                Windows
d-----       29-01-2019     18:26                xampp
d-----       05-05-2019     12:53                xampplite
-a----       20-11-2019     04:26        4684056 aow_drv.log  

```

**示例 2:** 以下示例也仅使用了一个**用**捕捉**块，尝试**块:

```

Try
{
Get-Child
}
catch
{
"Error in a Try block."
}

```

在本例中，Try 块中的命令是错误的，因此 Try 块中存在错误。因此，我们得到 catch 块的输出:

```
Error in a Try block.

```

* * *